Workbook
Name ИмяСтрахователя: Основной!$E$7
Name поиск1: OFFSET(перечень!$B$1,MATCH(Основной!$B$32,перечень!$B:$B,0)-1,1,COUNTIF(перечень!$B:$B,Основной!$B$32),1)

Sheet Основной
A2: Заявление-вопросник на страхование имущества
A4: 1. Просим Вас заполнить ВСЕ обязательные графы (отмечены звездочкой *) настоящего заявления-вопросника. Неполное заполнение заявления дает право СПАО "Ингосстрах" не принять заявление Страхователя и воздержаться от предоставления страхового покрытия, а неотвеченные вопросы приравниваются к ответу с наихудшим значением для целей определения параметров и стоимости страховой защиты. 2. Заявление-вопросник должно быть подписано руководителем или уполномоченным лицом Страхователя. 3. Просим Вас подписать и скрепить печатью каждую страницу.
A6: 1.1. | B6: Информация о Страхователе
B7: Наименование Страхователя:
B8: Юридический адрес:
B9: ИНН:
B10: Контактное лицо:
B11: Телефон: | F11: E-mail:
G12: Является способом взаимодействия со Страхователем.
A13: 1.2. | B13: Информация о Выгодоприобретателе Необходимо заполнить, если иное, чем Страхователь лицо.
B14: Наименование Выгодоприобретателя: | E14: ООО Сторук Воронеж
B15: Юридический адрес:
B16: ИНН: | E16: 3665806928
B17: На основании договора (залога/иное):
B18: № договора (залога/лизинга/иное): | G18: Действует с: | J18: по:
B19: Данные контактного лица (ФИО, должность, телефон/факс, e-mail):
A21: 1.3.* | B21: Укажите необходимый период страхования | F21: с: | I21: по:
A22: 1.4.* | B22: Информация о территории страхования Место расположения объектов страхования. Точный адрес. Если необходимо, с указанием номера корпуса, офиса и т.д.
B23: Страна: | I23: Индекс:
B24: Область/субъект:
B25: Район:
B26: Населенный пункт:
B27: Улица:
B28: Дом: | F28: Корпус: | I28: Строение:
B29: Дополнительно:
A30: 2. | B30: Информация об объектах страхования, страховых суммах, страховых рисках
A31: 2.1.* | B31: 2.1.1. Выберите основное назначение заявляемого на страхование имущества:
B33: 2.1.2. Выберите категорию:
A35: 2.2. | B35: Дайте краткое описание имущества, заявляемого на страхование:
A37: 2.3.* | B37: Укажите валюту, в которой выражена стоимость имущества:
A39: 2.4.* | B39: Укажите, на базе какой стоимости установлена страховая сумма:
B42: Включен ли в страховую сумму НДС?
A44: 2.5.* | B44: Выберите и укажите только те объекты, которые необходимо застраховать, укажите их страховую сумму. По возможности, приложите к заявлению перечень заявляемого на страхование имущества. Если выбрано страхование "по первому риску", укажите так же их страховую стоимость.
B45: Вид объекта, заявляемого на страхование: | H45: Страховая сумма: * | J45: Страховая стоимость:
B46: Здание или часть здания (конструктивные элементы, внутренняя и внешняя отделка).
B47: Здание или часть здания (конструктивные элементы, инженерные коммуникации), исключая отделку.
B48: Внешняя отделка здания или части здания, исключая дополнительные надстройки и оборудование.
B49: Внутренняя отделка помещений.
B50: Внешние сооружения и результаты работ по благоустройству территории страхования (ограды, шлагбаумы, рекламные щиты и вывески и т.п.).
B51: Оконные стекла, витрины, стеклопакеты, стеклянные элементы входных групп, дверей (если страхуются отдельной суммой).
...

Sheet MB
A1: Дополнительное заявление на страхование "Поломки машин и оборудования"
A3: 1. | B3: Укажите общую страховую сумму заявляемых на страхование от поломок машин и оборудования. Если на основном листе было выбрано страхование "по первому риску", укажите так же общую страховую стоимость.
B4: Страховая сумма: | G4: Страховая стоимость:
A5: 2. | B5: Выберите необходимый объем страхового покрытия: *
A7: 3. | B7: Приложите к заявлению перечень заявляемых на страхование машин и оборудования по форме, приведенной ниже.
B9: № п/п | C9: Наименование объекта, заявляемого на страхование: | F9: Год выпуска: | G9: Страховая сумма: | I9: Страховая стоимость:
B10: 1
B11: …

Sheet BI
A1: Дополнительное заявление на страхование "Убытки от перерыва в производственной (комерческой) деятельности"
A3: 1. | B3: Укажите необходимый период (в месяцах) возмещения:
A4: 2. | B4: Объекты страхования/статьи расходов: | J4: Страховая сумма:
B5: Заработная плата рабочих и служащих Страхователя
B6: Платежи органам социального страхования и аналогичные им платежи
B7: Плата за аренду помещений, оборудования или иного арендуемого имущества
B8: Налоги и сборы, подлежащие оплате вне зависимости от оборота и результатов хозяйственной деятельности
B9: Проценты по кредитам или иным привлеченным средствам
B10: Амортизационные отчисления по нормам, установленным для предприятия Страхователя
B11: Сумма чистой прибыли (прибыли после налогообложения)
B12: Сумма поступлений арендных платежей (платежей от сдачи в аренду помещений)
B13: Свой вариант 1 (указать наименование)
B14: Свой вариант 2 (указать наименование)
B15: Справочно, страховая сумма итого: | J15: =J5+J6+J7+J8+J9+J10+J11+J12+J13+J14 -> 0
A16: 3. | B16: Расширения страхового покрытия (CBI):

Sheet EE
A1: Дополнительное заявление на страхование "Электрические поломки оборудования"
A3: 1. | B3: Укажите общую страховую сумму заявляемого на страхование от электрических поломок оборудования. Если на основном листе было выбрано страхование "по первому риску", укажите так же общую страховую стоимость.
B4: Страховая сумма: | G4: Страховая стоимость:
A5: 2. | B5: Выберите необходимый объем страхового покрытия: *
A7: 3. | B7: Приложите к заявлению перечень заявляемого на страхование оборудования по форме, приведенной ниже.
B9: № п/п | C9: Наименование объекта, заявляемого на страхование: | F9: Год выпуска: | G9: Страховая сумма: | I9: Страховая стоимость:
B10: 1
B11: …

Sheet Авто
A1: Дополнительное заявление на страхование "Автомобили на стоянках, в помещениях автосервисов и автодилеров"
A3: 1. | B3: 1.1. Где и как хранятся документы на машины?
B4: 1.2. Где и как хранятся ключи на машины?
B5: 1.3. Сколько бензина залито (л)?
A6: 2. | B6: При наличии открытой стоянки.
B7: 2.1. Количество въездов/выездов:
B8: 2.2. Высота ограждения (м):
B9: 2.3. Порядок въезда и выезда:
B10: 2.4. Эксплуатация стоянки только страхователем или нет?
B11: 2.5. Наличие видеокамер, контролирующих свыше 80% территории:
B12: 2.6. Наличие сторожевых собак:
B13: 2.7. Обход территории:
B14: 2.8. Находятся ли автомобиле в прямой видимости охраны?

Sheet ТМЦ в холодильнике
A1: Дополнительное заявление на страхование "Страхование имущества от несоблюдения (нарушения) температурного режима"
A3: 1. | B3: Выберите необходимый объем страхового покрытия: *
A5: 2. | B5: Характеристика холодильного сооружения.
B6: 2.1. Количество независимых холодильных контуров:
B7: 2.2. Количество холодильных камер (отсеков):
B8: 2.3. Объем морозильных камер (кв.м):
B9: 2.4. Общая площадь холодильных камер (куб.м):
B10: 2.5. Высота (м):
B11: 2.6. Температура в камерах:
B12: 2.7. Содержание СО2 (%):
B13: 2.8. Содержание О2 (%):
B14: 2.9. Относительная влажность воздуха (%):
B15: 2.10. Давление воздуха (атм):
B16: 2.11. Наличие резервных источников электроэнергии:
B17: 2.12. Количество электрических вводов на предприятие (в здание):
... B21: 2.16. Дата последней замены изоляции:
A22: 3. | B22: Характеристика холодильной установки.
B23: 3.1. Дата ввода в эксплуатацию:
B24: 3.2. Укажите, кто осуществляет технадзор:
B25: 3.3. Инспекции проводятся с нормативной периодичностью?
B26: 3.4. Текущий ремонт проводится с нормативной периодичностью?
B27: 3.5. Кто проводит текущий ремонт?
B28: 3.6. Данная холодильная установка является собственностью?
B29: 3.7. Период времени в соответствии с технической документацией, в течение которого холодильная установка может сохранять заданный температурный режим при отключении электропитания или ее непредвиденной поломке, в часах:
A30: 4. | B30: Характеристика систем контроля и сигнализации.
B31: 4.1. Число и тип датчиков (температуры, влажности, СО2, СО, давления) в каждой камере:
B32: 4.2. Интервалы контроля, в часах:
B33: 4.3. Имеются ли сигнализаторы?
A34: 5. | B34: Резервные холодильные сооружения (наличие, адрес, какой % товара может быть перемещен).
B35: 5.1. Наличие:
B36: 5.2. Адрес:
B37: 5.3. Какой % товара может быть перемещен?

Sheet Ювелирные изделия и меха
A1: Дополнительное заявление на страхование "Ювелирные изделия, драгоценные камни и металлы, меха"
A3: 1. | B3: 1.1. Максимальная стоимость единицы ювелирных изделий, драгоценных камней и металлов (в рублях), мехов (если более 300 т.р. – приложить документы):
B4: 1.2. При наличии ЧОПа – указать реквизиты и приложить копию договора охраны:
B5: 1.3. Наличие исправной автоматической охранной сигнализации с выводом на пульт охраны (МВД, ЧОП и т.п.):
B6: 1.4. Наличие датчиков на все стекла и двери, а также на движение внутри помещения:
B7: 1.5. Остекление торговых витрин противоударное и без свободного доступа к изделиям со стороны покупателей и третьих лиц?
B8: 1.6. Площадь (объем) помещений, контролируемая извещателями:
B9: 1.7. Дверные проёмы, люки, ворота блокируются на «открывание» и «пролом»?
B10: 1.8. Остекленные конструкции блокируются на «открывание» и разрушение стекла?
B11: 1.9. Металлические двери, ворота блокируются на «открывание» и ударное воздействие?
B12: 1.10. Некапитальные стены, потолки и места ввода коммуникаций блокируются на «пролом»?
B13: 1.11. Капитальные стены, вентиляционные короба блокируются на разрушение и удар. Воздействие?
B14: 1.12. При отключении сетевого электропитания работоспособность ПКП (приемно-контрольный прибор) и извещателей обеспечена автономным питанием на 8 часов?
B15: 1.13. Во внерабочее время ценности убираются в сейф в сейфовую комнату?
... B17: 1.15. Сейф/сейфовая комната соответствует классу устойчивости к взлому не ниже 2?

Sheet перечень
A1: Номер | B1: Отрасль | C1: Суботрасль | G1: Авто-мотосалоны, авто-мотосервисы, автоломбарды и автодилеры | K1: Автозапчасти, автомобили, машиностроение
A2: 1 | B2: Текстильная промышленность, производство одежды, обуви | C2: Текстильная промышленность, производство одежды, обуви | G2: АЗС, ГАЗС, электрические заправки | K2: Алкогольная продукция
A3: 2.1. | B3: Лесная, деревообрабатывающая и целлюлозно-бумажная промышленность | C3: Заготовка и обработка древесины | G3: Горно-металлургические предприятия | K3: Аудио-, видеотехника, электромузыкальные инструменты, оргтехника и т.п., за исключением мобильных устройств, средств связи, фото и киноаппаратуры, оптики, часов
A4: 2.2. | B4: Лесная, деревообрабатывающая и целлюлозно-бумажная промышленность | C4: Производство изделий из древесины | G4: Гостиницы, дома отдыха, туристические базы | K4: Безалкогольные напитки
A5: 2.3. | B5: Лесная, деревообрабатывающая и целлюлозно-бумажная промышленность | C5: Целлюлозно-бумажные комбинаты | G5: Добыча полезных ископаемых (кроме нефти, газа) | K5: Бытовая химия (стиральные порошки, чистящие и моющие средства, удобрения, химикаты и т.п.)
A6: 3.1. | B6: Производство строительных материалов | C6: Производство цемента | G6: Жилая недвижимость, ТСЖ | K6: Взрывчатые и легковоспламеняющиеся жидкие вещества
A7: 3.2. | B7: Производство строительных материалов | C7: Производство стекла | G7: Жилищно-коммунальное хозяйство | K7: Галантерея (металлическая, пластмассовая и кожгалантерея, бижутерия, швейная фурнитура и т.п.)
A8: 3.3. | B8: Производство строительных материалов | C8: Производство кирпича, плитки, огнеупоров | G8: Лесная, деревообрабатывающая и целлюлозно-бумажная промышленность | K8: Имущество, не входящее в указанные группы
A9: 3.4. | B9: Производство строительных материалов | C9: Производство асфальта, битума | G9: Машиностроение и приборостроение | K9: Книги, журналы, другая полиграфическая продукция
A10: 3.5. | B10: Производство строительных материалов | C10: Производство прочих стройматериалов | G10: Медицинские учреждения (больницы, поликлиники, санатории) | K10: Мебель
A11: 4.1. | B11: Добыча полезных ископаемых (кроме нефти, газа) | C11: Добыча открытым способом (карьеры, разрезы) полезных ископаемых, минералов и сырья | G11: Научно-исследовательские лаборатории и т.п. | K11: Металлопрокат и прочая продукция металлургических заводов и комбинатов
A12: 4.2. | B12: Добыча полезных ископаемых (кроме нефти, газа) | C12: Добыча закрытым способом (шахты, рудники) полезных ископаемых, минералов и сырья, кроме угля | G12: Нефтяная/газовая промышленность | K12: Мобильные устройства (сотовые телефоны и т.п.), средства связи (телефонные аппараты, автоответчики, факсы и т.п.)
A13: 4.3. | B13: Добыча полезных ископаемых (кроме нефти, газа) | C13: Добыча угля закрытым способом (шахты, рудники) | G13: Объекты культуры, искусства, развлечений | K13: Нефасованный чай, кофе (категория выбирается в том случае, если доля нефасованного чая или кофе составляет более 50% от общей страховой суммы ТМЦ по территории страхования)
A14: 5.1. | B14: Горно-металлургические предприятия | C14: Металлургические комбинаты и заводы | G14: Объекты образования | K14: Одежда, головные уборы из натуральной кожи и натурального меха
... A28: 9.3. | B28: Электроэнергетика | C28: Атомные электростанции (АЭС) | G28: Химическая и нефтехимическая промышленность | K28: Ювелирные изделия
A29: 9.4. | B29: Электроэнергетика | C29: Передача (распределение) электроэнергии (электрические сети, подстанции) | G29: Хранение и обработка информации, ЦОД, телекоммуникации и связь
A30: 9.5. | B30: Электроэнергетика | C30: Возобновляемая энергетика (солнечные, ветровые, приливные, геотермальные и т.п. электростанции) | G30: Электроэнергетика
A31: 10.1. | B31: Пищевая промышленность | C31: Производство продуктов питания, безалкогольных напитков
A32: 10.2. | B32: Пищевая промышленность | C32: Производство сахара
A33: 10.3. | B33: Пищевая промышленность | C33: Масло-жировые комбинаты
A34: 10.4. | B34: Пищевая промышленность | C34: Производство алкогольных напитков
A35: 11 | B35: Прочие промышленные предприятия (обязательно указание) | C35: Прочие промышленные предприятия (обязательно указание)
A36: 1.1. | B36: Офисная недвижимость, адм. здания | C36: Коммерческого назначения
A37: 1.2. | B37: Офисная недвижимость, адм. здания | C37: Для государственных нужд
A38: 2.1. | B38: Торговля, торговая и торгово-развлекательная недвижимость | C38: Многофункциональная торговая недвижимость
A39: 2.2. | B39: Торговля, торговая и торгово-развлекательная недвижимость | C39: Предприятия торговли (за исключением антикварных салонов и ломбардов)
A40: 2.3. | B40: Торговля, торговая и торгово-развлекательная недвижимость | C40: Ломбарды, аукционные дома, антикварные салоны
A41: 3 | B41: Складская деятельность, логистика | C41: Складская деятельность, логистика
A42: 4 | B42: Авто-мотосалоны, авто-мотосервисы, автоломбарды и автодилеры | C42: Авто-мотосалоны, авто-мотосервисы, автоломбарды и автодилеры
A43: 5 | B43: Рестораны, кафе, бары, предприятия общественного питания | C43: Рестораны, кафе, бары, предприятия общественного питания
A44: 6 | B44: Гостиницы, дома отдыха, туристические базы | C44: Гостиницы, дома отдыха, туристические базы
A45: 7.1. | B45: Спортивные и оздоровительные объекты | C45: Стадионы, бассейны, фитнес-клубы, спортзалы
A46: 7.2. | B46: Спортивные и оздоровительные объекты | C46: Горнолыжные курорты / объекты
A47: 8 | B47: Медицинские учреждения (больницы, поликлиники, санатории) | C47: Медицинские учреждения (больницы, поликлиники, санатории)
A48: 9 | B48: Объекты образования | C48: Объекты образования
A49: 10 | B49: Научно-исследовательские лаборатории и т.п. | C49: Научно-исследовательские лаборатории и т.п.
A50: 11.1. | B50: Объекты культуры, искусства, развлечений | C50: Аттракционы, парки развлечений
A51: 11.2. | B51: Объекты культуры, искусства, развлечений | C51: Кинотеатры, театры, концертные залы, цирк, развлекательные комплексы
A52: 11.3. | B52: Объекты культуры, искусства, развлечений | C52: Музеи, выставки, галереи
A53: 11.4. | B53: Объекты культуры, искусства, развлечений | C53: Ночные клубы, дискотеки, казино
...

Sheet Export
A1: Основной | F1: SYSDATE | G1: YEAR | I1: v.18_4
A2: № | B2: Раздел | C2: Пункт | D2: Значение | F2: =TODAY() -> 46255 | G2: =YEAR(F2) -> 2026
A3: 1 | B3: Информация о Страхователе | C3: Наименование Страхователя: | D3: =ИмяСтрахователя -> 0
A4: 2 | C4: Юридический адрес Страхователя: | D4: =Основной!E8 -> 0
A5: 3 | C5: ИНН Страхователя: | D5: =Основной!E9 -> 0
A6: 4 | C6: Контактное лицо Страхователя: | D6: =Основной!E10 -> 0
A7: 5 | C7: Телефон страхователя: | D7: =Основной!C11 -> 0
A8: 6 | C8: Email Страхователя | D8: =Основной!G11 -> 0
A9: 7 | B9: Информация о Выгодоприобретателе | C9: Наименование Выгодоприобретателя: | D9: =Основной!E14 -> ООО Сторук Воронеж
A10: 8 | C10: Юридический адрес Выгодоприобретателя: | D10: =Основной!E15 -> 0
A11: 9 | C11: ИНН Выгодоприобретателя: | D11: =Основной!E16 -> 3665806928
A12: 10 | C12: Договор-основание Выгодоприобретателя: | D12: =Основной!E17 -> 0
A13: 11 | C13: Номер Договора-основания: | D13: =Основной!E18 -> 0
A14: 12 | C14: Дата начала договора-основания: | D14: =Основной!I18 -> 0
A15: 13 | C15: Дата окончания договора-основания: | D15: =Основной!K18 -> 0
A16: 14 | C16: Контактная информация Выгодоприобретателя: | D16: =Основной!B20 -> 0
A17: 15 | B17: Период страхования | C17: Дата начала периода страхования: | D17: =Основной!G21 -> 0
A18: 16 | C18: Дата окончания периода страхования: | D18: =Основной!J21 -> 0
A19: 17 | B19: Территория страхования | C19: Страна | D19: =Основной!D23 -> 0
A20: 18 | C20: Индекс | D20: =Основной!J23 -> 0
A21: 19 | C21: Субъект / Область | D21: =Основной!D24 -> 0
A22: 20 | C22: Район | D22: =Основной!D25 -> 0
A23: 21 | C23: Населенный пункт | D23: =Основной!D26 -> 0
A24: 22 | C24: Улица | D24: =Основной!D27 -> 0
A25: 23 | C25: Дом | D25: =Основной!D28 -> 0
A26: 24 | C26: Корпус | D26: =Основной!G28 -> 0
A27: 25 | C27: Строение | D27: =Основной!J28 -> 0
A28: 26 | C28: Дополнительно | D28: =Основной!D29 -> 0
A29: 27 | B29: Общая хар-ка объектов страхования | C29: Основное назначение имущества | D29: =Основной!B32 -> 0
A30: 28 | C30: Категория имущества | D30: =Основной!B34 -> 0
A31: 29 | C31: Описание имущества | D31: =Основной!B36 -> 0
A32: 30 | C32: Валюта страхования | D32: 0
A33: 31 | C33: Иная валюта страхования | D33: =Основной!G38 -> 0
A34: 32 | C34: База стоимости | D34: 1
A35: 33 | C35: Иная база стоимости | D35: =Основной!D41 -> 0
A36: 34 | C36: НДС | D36: 0
A37: 35 | C37: Первый риск | D37: FALSE
A38: 36 | B38: Здание (конструктивные элементы, внутр. и внеш. отделка). | C38: Страховая сумма | D38: =Основной!H46 -> 0
A39: 37 | C39: Страховая стоимость | D39: =Основной!J46 -> 0
A40: 38 | B40: Здание (конструктивные элементы, инженерные коммуникации), исключая отделку. | C40: Страховая сумма | D40: =Основной!H47 -> 0
...
